Workbook

Sheet Instructions
A1: AEGIS FDE Day-wise Task Tracker (management)
A3: Source of truth: AEGIS_FDE_DAYWISE_TASK_DISTRIBUTION.md (v1.4) + this workbook.
A4: Regenerate: python -B submission/artefacts/ProjectPlan/export_daywise_tracker.py
A6: Columns (tracking)
A7: Date/Day · Module/Workstream · Task · Task Details · Assigned To · Priority · Status ·
A8: Start / Expected / Actual Completion · Dependencies · Blockers/Remarks · Completion %
A10: Preserved audit columns: Task ID, Reviewer, Gate, FINAL ref, Evaluation criteria, Result, Evidence path
A12: Dropdowns
A13: Priority: Low | Medium | High | Critical
A14: Status: Not Started | In Progress | Blocked | Completed | On Hold
A15: Result: PASS | FAIL | CONDITIONAL | N/A
A17: Formatting
... A24: Calendar: D1 = 2026-08-04 (Option B+ sequential session days).

Sheet Task_Tracker
A1: Date / Day | B1: Module / Workstream | C1: Task ID | D1: Task | E1: Task Details | F1: Assigned To | G1: Priority | H1: Status | I1: Start Date | J1: Expected Completion Date | K1: Actual Completion Date | L1: Dependencies | M1: Blockers / Remarks | N1: Completion Percentage | O1: Reviewer | P1: Gate | Q1: FINAL ref | R1: Evaluation criteria | S1: Result | T1: Evidence path
A2: D1 | B2: P0 Preflight | C2: D1-T1 | D2: Hour-0 preflight; archive VALIDATION_REPORT.json | E2: What to implement: Hour-0 preflight; archive VALIDATION_REPORT.json Expected functionality: Run `python -B run_capstone.py --check` once. Copy/archive VALIDATION_REPORT.json under submission/evidence/ with timestamp. Do not re-run until defence unless challenge tree integrity is in doubt. Log command + result in decision log. Important considerations: Work only under submission/; preserve immutable challenge evidence; Agents OFF until G4 PASS. FINAL ref §4.2, §8 P0. Reviewer FDE-5 (author ≠ sole approver). Gate context: Preflight. Expected output / completion criteria: Command uses python -B; report status PASS; archive path under submission/evidence/; timestamp logged | F2: FDE-3 | G2: Critical | H2: Not Started | I2: 46238 | J2: 46238 | L2: Kickoff / package available | N2: 0 | O2: FDE-5 | P2: Preflight | Q2: §4.2, §8 P0 | R2: Command uses python -B; report status PASS; archive path under submission/evidence/; timestamp logged
A3: D1 | B3: P0 Preflight | C3: D1-T2 | D3: Scaffold submission dirs; -B convention | E3: What to implement: Scaffold submission dirs; -B convention Expected functionality: Create submission tree via check_submission_structure.py --scaffold. Ensure app/, src/, tests/, evaluation/, artefacts/, evidence/, runbooks/, scripts/ exist. Document that all Python invocations use python -B. Important considerations: Work only under submission/; preserve immutable challenge evidence; Agents OFF until G4 PASS. FINAL ref §7.2, §8 P0. Reviewer FDE-1 (author ≠ sole approver). Gate context: Preflight. Expected output / completion criteria: check_submission_structure.py --scaffold PASS; dirs app/src/tests/evaluation/artefacts/evidence/runbooks/scripts exist | F3: FDE-3 | G3: Critical | H3: Not Started | I3: 46238 | J3: 46238 | L3: Kickoff / package available | N3: 0 | O3: FDE-1 | P3: Preflight | Q3: §7.2, §8 P0 | R3: check_submission_structure.py --scaffold PASS; dirs app/src/tests/evaluation/artefacts/evidence/runbooks/scripts exist
A4: D1 | B4: P0 Preflight | C4: D1-T3 | D4: Team charter + SCQA; open Assumptions/Decision/RAID logs | E4: What to implement: Team charter + SCQA; open Assumptions/Decision/RAID logs Expected functionality: Write short charter (SCQA + seats + prohibited AI actions). Create assumptions, decision, and RAID logs under submission/evidence/. Name FDE-1…5 ↔ P1…P5. Confirm dual-track honesty language. Important considerations: Work only under submission/; preserve immutable challenge evidence; Agents OFF until G4 PASS. FINAL ref §8 P0, §17, §21. Reviewer FDE-4 (author ≠ sole approver). Gate context: Preflight. Expected output / completion criteria: Charter lists prohibited AI actions; logs exist under submission/evidence/; seats named | F4: FDE-1 | G4: Critical | H4: Not Started | I4: 46238 | J4: 46238 | L4: Kickoff / package available | N4: 0 | O4: FDE-4 | P4: Preflight | Q4: §8 P0, §17, §21 | R4: Charter lists prohibited AI actions; logs exist under submission/evidence/; seats named
A5: D1 | B5: P0 Preflight | C5: D1-T4 | D5: Case + inject catalogue skim; D01–D13 hotspots | E5: What to implement: Case + inject catalogue skim; D01–D13 hotspots Expected functionality: Read INTEGRATED_CASE and injects.json. Produce hotspot list for D01–D13 (batch/PV/supply/privacy/security). Explicitly do not “fix” deliberate conflicts or normalize units/IDs. Important considerations: Work only under submission/; preserve immutable challenge evidence; Agents OFF until G4 PASS. FINAL ref §3, §8 P0. Reviewer FDE-3 (author ≠ sole approver). Gate context: Preflight. Expected output / completion criteria: Written hotspot list citing INTEGRATED_CASE / injects.json; no conflict “fixes” | F5: FDE-2 | G5: Critical | H5: Not Started | I5: 46238 | J5: 46238 | L5: Kickoff / package available | N5: 0 | O5: FDE-3 | P5: Preflight | Q5: §3, §8 P0 | R5: Written hotspot list citing INTEGRATED_CASE / injects.json; no conflict “fixes”
A6: D1 | B6: P0 Preflight | C6: D1-T5 | D6: Prohibited-action catalogue from ai_use_boundaries + decision_rights | E6: What to implement: Prohibited-action catalogue from ai_use_boundaries + decision_rights Expected functionality: Extract forbid lists from challenge CSVs. Map each forbid to Workflow A/B/C. Catalogue becomes input to G1 artefacts and G3/G4 contracts. Important considerations: Work only under submission/; preserve immutable challenge evidence; Agents OFF until G4 PASS. FINAL ref §1, §3.2, §8 P1 prep. Reviewer FDE-5 (author ≠ sole approver). Gate context: Preflight. Expected output / completion criteria: Catalogue covers batch/PV/supply forbids; cites CSV paths; maps to WF A/B/C | F6: FDE-4 | G6: Critical | H6: Not Started | I6: 46238 | J6: 46238 | L6: Kickoff / package available | N6: 0 | O6: FDE-5 | P6: Preflight | Q6: §1, §3.2, §8 P1 prep | R6: Catalogue covers batch/PV/supply forbids; cites CSV paths; maps to WF A/B/C
A7: D1 | B7: P0 Preflight | C7: D1-T6 | D7: Security/privacy stop lines; flag INJ-065/066/067 | E7: What to implement: Security/privacy stop lines; flag INJ-065/066/067 Expected functionality: Write deny-by-default stop lines for tool poisoning, unsigned tools, stale auth. Reference INJ-065/066/067. Feed into threat artefact and failing tests later. Important considerations: Work only under submission/; preserve immutable challenge evidence; Agents OFF until G4 PASS. FINAL ref §3.4, §11. Reviewer FDE-4 (author ≠ sole approver). Gate context: Preflight. Expected output / completion criteria: Stop lines written; three inject IDs referenced; deny-by-default stated | F7: FDE-5 | G7: Critical | H7: Not Started | I7: 46238 | J7: 46238 | L7: Kickoff / package available | N7: 0 | O7: FDE-4 | P7: Preflight | Q7: §3.4, §11 | R7: Stop lines written; three inject IDs referenced; deny-by-default stated
A8: D1 | B8: P0 Preflight | C8: D1-T7 | D8: Ratify AEGIS_PROJECT_PLAN_FINAL.md | E8: What to implement: Ratify AEGIS_PROJECT_PLAN_FINAL.md Expected functionality: Team agrees FINAL v1.1+ is governing SoT. Decision-log entry with version, date, dual-track honesty. Supersedes V1–V4 for execution. Important considerations: Work only under submission/; preserve immutable challenge evidence; Agents OFF until G4 PASS. FINAL ref §21. Reviewer FDE-1 records (author ≠ sole approver). Gate context: Preflight. Expected output / completion criteria: Decision-log entry: ratified version + date; dual-track honesty acknowledged | F8: All | G8: Critical | H8: Not Started | I8: 46238 | J8: 46238 | L8: D1-T1; D1-T2; D1-T3 | N8: 0 | O8: FDE-1 records | P8: Preflight | Q8: §21 | R8: Decision-log entry: ratified version + date; dual-track honesty acknowledged
A9: D1 | B9: P0 Preflight | C9: D1-T8 | D9: Eval step 1: document brownfield understanding | E9: What to implement: Eval step 1: document brownfield understanding Expected functionality: Capture workflows, I/O, evidence sources, tools/APIs, rules/restrictions, existing tests, failure handling, human approval points. Cite starter/ and contracts. Write to submission/evaluation/README.md or evidence/repo_understanding.md. Important considerations: Work only under submission/; preserve immutable challenge evidence; Agents OFF until G4 PASS. FINAL ref §11.8 step 1. Reviewer FDE-2 (author ≠ sole approver). Gate context: Preflight. Expected output / completion criteria: Written note covering all eight topics; cites starter/ + contracts | F9: FDE-5 (+FDE-3) | G9: Critical | H9: Not Started | I9: 46238 | J9: 46238 | L9: D1-T4 | N9: 0 | O9: FDE-2 | P9: Preflight | Q9: §11.8 step 1 | R9: Written note covering all eight topics; cites starter/ + contracts
A10: D1 | B10: P0 Preflight | C10: D1-T9 | D10: Create finops_delivery_log.csv; seed D1 rows | E10: What to implement: Create finops_delivery_log.csv; seed D1 rows Expected functionality: Create submission/evidence/finops_delivery_log.csv with columns: date, task_id, chat_sessions, files_attached, agent_iterations, terminal_commands, files_modified, failed_attempts, full_suite_runs, task_outcome. Each seat logs ≥1 D1 row; agent_iterations=0 until G4. Important considerations: Work only under submission/; preserve immutable challenge evidence; Agents OFF until G4 PASS. FINAL ref §11.9. Reviewer FDE-5 (author ≠ sole approver). Gate context: Preflight. Expected output / completion criteria: Header matches §0.3; each seat has ≥1 row for D1; agent_iterations=0 | F10: FDE-1 | G10: Critical | H10: Not Started | I10: 46238 | J10: 46238 | L10: D1-T3 | N10: 0 | O10: FDE-5 | P10: Preflight | Q10: §11.9 | R10: Header matches §0.3; each seat has ≥1 row for D1; agent_iterations=0
A11: D2 | B11: P1 Discovery / G1 | C11: D2-T1 | D11: Draft artefacts 01–04 | E11: What to implement: Draft artefacts 01–04 Expected functionality: Produce problem/value (01), business case (02), stakeholders (03), AI blueprint/boundaries (04). Cite BR-01, kpi_conflicts, stakeholders, ai_use_boundaries. Label FACT vs ASSUMPTION. Meet substantive length rules. Important considerations: Work only under submission/; preserve immutable challenge evidence; Agents OFF until G4 PASS. FINAL ref §8 P1, §12. Reviewer FDE-4 (01–03), FDE-5 (04) (author ≠ sole approver). Gate context: G1. Expected output / completion criteria: Each cites BR-01 / kpi_conflicts / stakeholders / ai_use_boundaries as applicable; FACT/ASSUMPTION labels; ≥ substantive length | F11: FDE-1 | G11: Critical | H11: Not Started | I11: 46239 | J11: 46239 | L11: D1-T7 | N11: 0 | O11: FDE-4 (01–03), FDE-5 (04) | P11: G1 | Q11: §8 P1, §12 | R11: Each cites BR-01 / kpi_conflicts / stakeholders / ai_use_boundaries as applicable; FACT/ASSUMPTION labels; ≥ substantive length
A12: D2 | B12: P1 Discovery / G1 | C12: D2-T2 | D12: No-AI comparison + stop/pivot | E12: What to implement: No-AI comparison + stop/pivot Expected functionality: Compare master_data_repair vs rules vs GenAI paths. Document stop/pivot/pause/abstain triggers including prohibited autonomy. Keep honest about when AI is not needed. Important considerations: Work only under submission/; preserve immutable challenge evidence; Agents OFF until G4 PASS. FINAL ref §3.3, §3.4. Reviewer FDE-5 (author ≠ sole approver). Gate context: G1. Expected output / completion criteria: master_data_repair / rules / genai table present; stop triggers include prohibited autonomy | F12: FDE-1 | G12: Critical | H12: Not Started | I12: 46239 | J12: 46239 | L12: D2-T1 | N12: 0 | O12: FDE-5 | P12: G1 | Q12: §3.3, §3.4 | R12: master_data_repair / rules / genai table present; stop triggers include prohibited autonomy
A13: D2 | B13: P1 Discovery / G1 | C13: D2-T3 | D13: Lock production NFRs @ G1 | E13: What to implement: Lock production NFRs @ G1 Expected functionality: Fill all 8 NFR rows (availability through compliance). No certification or ISO-conformant overclaim. Lock table at G1 for later soak/FinOps checks. Important considerations: Work only under submission/; preserve immutable challenge evidence; Agents OFF until G4 PASS. FINAL ref §5.3. Reviewer FDE-5 (author ≠ sole approver). Gate context: G1. Expected output / completion criteria: All 8 NFR rows filled; no certification overclaim | F13: FDE-1 | G13: Critical | H13: Not Started | I13: 46239 | J13: 46239 | L13: D2-T1 | N13: 0 | O13: FDE-5 | P13: G1 | Q13: §5.3 | R13: All 8 NFR rows filled; no certification overclaim
... A17: D2 | B17: P1 Discovery / G1 | C17: D2-T7 | D17: Review 04; NFR sec/privacy rows | E17: What to implement: Review 04; NFR sec/privacy rows Expected functionality: Review artefact 04 and NFR security/privacy bars. Confirm prohibited uses are explicit and measurable. Important considerations: Work only under submission/; preserve immutable challenge evidence; Agents OFF until G4 PASS. FINAL ref §12, §5.3. Reviewer FDE-1 (ack) (author ≠ sole approver). Gate context: G1. Expected output / completion criteria: Review confirms prohibited uses + privacy/security NFR bars | F17: FDE-5 | G17: Critical | H17: Not Started | I17: 46239 | J17: 46239 | L17: D2-T1; D2-T3 | N17: 0 | O17: FDE-1 (ack) | P17: G1 | Q17: §12, §5.3 | R17: Review confirms prohibited uses + privacy/security NFR bars
A18: D3 | B18: P2 Domain | C18: D3-T1 | D18: Draft 05 DDD + 06 Data gov | E18: What to implement: Draft 05 DDD + 06 Data gov Expected functionality: Bounded contexts for WF A/B/C. State ALCOA+ and no silent normalize. Artefact 06 must be hard-gate aware (authority, effective date, units). Important considerations: Work only under submission/; preserve immutable challenge evidence; Agents OFF until G4 PASS. FINAL ref §8 P2, §12. Reviewer FDE-3 (05), FDE-4 (06) (author ≠ sole approver). Gate context: day exit / phase checkpoint. Expected output / completion criteria: Bounded contexts for A/B/C; ALCOA+/no silent normalize stated; 06 hard-gate aware | F18: FDE-2 | G18: High | H18: Not Started | I18: 46240 | J18: 46240 | L18: G1 (D2) | N18: 0 | O18: FDE-3 (05), FDE-4 (06) | Q18: §8 P2, §12 | R18: Bounded contexts for A/B/C; ALCOA+/no silent normalize stated; 06 hard-gate aware
A19: D3 | B19: P2 Domain | C19: D3-T2 | D19: Start 84-inject register mirror | E19: What to implement: Start 84-inject register mirror Expected functionality: Mirror INJECT_TEST_COVERAGE under submission/evaluation/. Leave challenge CSV untouched. All rows start NOT_RUN; progress must be countable. Important considerations: Work only under submission/; preserve immutable challenge evidence; Agents OFF until G4 PASS. FINAL ref §11.1. Reviewer FDE-4 (author ≠ sole approver). Gate context: day exit / phase checkpoint. Expected output / completion criteria: Mirror path under submission/evaluation/; challenge CSV untouched; progress countable | F19: FDE-2 | G19: High | H19: Not Started | I19: 46240 | J19: 46240 | L19: D1-T4 | N19: 0 | O19: FDE-4 | Q19: §11.1 | R19: Mirror path under submission/evaluation/; challenge CSV untouched; progress countable
A20: D3 | B20: P2 Domain | C20: D3-T3 | D20: RTM skeleton 09; RELATIONSHIP_MODEL checker design | E20: What to implement: RTM skeleton 09; RELATIONSHIP_MODEL checker design Expected functionality: Start artefact 09 RTM. Design checker that cites RELATIONSHIP_MODEL.csv and fails closed on ambiguous identity links. Unique RTM IDs. Important considerations: Work only under submission/; preserve immutable challenge evidence; Agents OFF until G4 PASS. FINAL ref §8 P2, §13. Reviewer FDE-5 (author ≠ sole approver). Gate context: day exit / phase checkpoint. Expected output / completion criteria: Checker design cites RELATIONSHIP_MODEL.csv; RTM IDs unique | F20: FDE-3 | G20: High | H20: Not Started | I20: 46240 | J20: 46240 | L20: D3-T1 | N20: 0 | O20: FDE-5 | Q20: §8 P2, §13 | R20: Checker design cites RELATIONSHIP_MODEL.csv; RTM IDs unique
A21: D3 | B21: P2 Domain | C21: D3-T4 | D21: Authority/provenance rules for 06; INJ-031 flag | E21: What to implement: Authority/provenance rules for 06; INJ-031 flag Expected functionality: Rules require status, authority, effective date. Log validation ambiguity as conflict (do not invent truth). Flag INJ-031. Important considerations: Work only under submission/; preserve immutable challenge evidence; Agents OFF until G4 PASS. FINAL ref §8 P2, §11. Reviewer FDE-2 (author ≠ sole approver). Gate context: day exit / phase checkpoint. Expected output / completion criteria: Rules require status/authority/effective date; validation ambiguity logged as conflict | F21: FDE-4 | G21: High | H21: Not Started | I21: 46240 | J21: 46240 | L21: Prior day exit (D2); seat capacity | N21: 0 | O21: FDE-2 | Q21: §8 P2, §11 | R21: Rules require status/authority/effective date; validation ambiguity logged as conflict
A22: D3 | B22: P2 Domain | C22: D3-T5 | D22: Privacy/residency flags in register (D09) | E22: What to implement: Privacy/residency flags in register (D09) Expected functionality: Tag INJ-059–064 in inject register. Do not silently minimize GxP holds for privacy convenience. Important considerations: Work only under submission/; preserve immutable challenge evidence; Agents OFF until G4 PASS. FINAL ref §11.1 D09. Reviewer FDE-4 (author ≠ sole approver). Gate context: day exit / phase checkpoint. Expected output / completion criteria: INJ-059–064 rows tagged; no silent minimization of GxP holds | F22: FDE-5 | G22: High | H22: Not Started | I22: 46240 | J22: 46240 | L22: Prior day exit (D2); seat capacity | N22: 0 | O22: FDE-4 | Q22: §11.1 D09 | R22: INJ-059–064 rows tagged; no silent minimization of GxP holds
A23: D3 | B23: P2 Domain | C23: D3-T6 | D23: Brownfield/TOM impact notes; global vs local conflict | E23: What to implement: Brownfield/TOM impact notes; global vs local conflict Expected functionality: Capture brownfield and TOM notes for artefact 26 later. Record global vs local conflict without premature resolution. Important considerations: Work only under submission/; preserve immutable challenge evidence; Agents OFF until G4 PASS. FINAL ref §6.3. Reviewer FDE-4 (author ≠ sole approver). Gate context: day exit / phase checkpoint. Expected output / completion criteria: Notes exist for later artefact 26; conflict not prematurely resolved | F23: FDE-1 | G23: High | H23: Not Started | I23: 46240 | J23: 46240 | L23: Prior day exit (D2); seat capacity | N23: 0 | O23: FDE-4 | Q23: §6.3 | R23: Notes exist for later artefact 26; conflict not prematurely resolved
A24: D3 | B24: P2 Domain | C24: D3-T7 | D24: Eval step 2: design eval-set coverage matrix | E24: What to implement: Eval step 2: design eval-set coverage matrix Expected functionality: Design cases: normal, edge, adversarial, metamorphic, outage. Include required/prohibited behaviours, escalation, hard-gate status. Store under evaluation/datasets/. expected_answer_included=no. Important considerations: Work only under submission/; preserve immutable challenge evidence; Agents OFF until G4 PASS. FINAL ref §11.8 step 2. Reviewer FDE-4 (author ≠ sole approver). Gate context: day exit / phase checkpoint. Expected output / completion criteria: Matrix under datasets/; maps to WF A/B/C + ≥1 row per suite family; expected_answer_included=no | F24: FDE-5 (+FDE-2) | G24: High | H24: Not Started | I24: 46240 | J24: 46240 | L24: D1-T8; D3-T2 | N24: 0 | O24: FDE-4 | Q24: §11.8 step 2 | R24: Matrix under datasets/; maps to WF A/B/C + ≥1 row per suite family; expected_answer_included=no
A25: D4 | B25: P2 Domain / G2 | C25: D4-T1 | D25: Complete 07 + 08 (KG + simpler alternative) | E25: What to implement: Complete 07 + 08 (KG + simpler alternative) Expected functionality: Finish ontology/KG artefacts. Artefact 08 must include simpler-alternative benchmark. No mandatory KG claim without evidence. Important considerations: Work only under submission/; preserve immutable challenge evidence; Agents OFF until G4 PASS. FINAL ref §8 P2, §12, §20. Reviewer FDE-3 (author ≠ sole approver). Gate context: G2. Expected output / completion criteria: 08 includes simpler-alternative benchmark; no mandatory KG claim without evidence | F25: FDE-2 | G25: Critical | H25: Not Started | I25: 46241 | J25: 46241 | L25: D3-T1 | N25: 0 | O25: FDE-3 | P25: G2 | Q25: §8 P2, §12, §20 | R25: 08 includes simpler-alternative benchmark; no mandatory KG claim without evidence
A26: D4 | B26: P2 Domain / G2 | C26: D4-T2 | D26: Inject register: all 84 off NOT_RUN or declared gap | E26: What to implement: Inject register: all 84 off NOT_RUN or declared gap Expected functionality: Every inject row either planned/mapped or declared gap in RAID/manifest. Count must equal 84. Never delete or silently resolve challenge rows. Important considerations: Work only under submission/; preserve immutable challenge evidence; Agents OFF until G4 PASS. FINAL ref §11.1. Reviewer FDE-1 (author ≠ sole approver). Gate context: G2. Expected output / completion criteria: Count = 84; gaps in RAID/manifest; challenge CSV unmodified | F26: FDE-2 | G26: Critical | H26: Not Started | I26: 46241 | J26: 46241 | L26: D3-T2; D3-T7 | N26: 0 | O26: FDE-1 | P26: G2 | Q26: §11.1 | R26: Count = 84; gaps in RAID/manifest; challenge CSV unmodified
A27: D4 | B27: P2 Domain / G2 | C27: D4-T3 | D27: RTM↔inject links; knowledge_catalog authority+hash stub | E27: What to implement: RTM↔inject links; knowledge_catalog authority+hash stub Expected functionality: Link RTM IDs to injects. Stub catalog gate that rejects superseded/untrusted sources when hash/status fail. Record demo evidence. Important considerations: Work only under submission/; preserve immutable challenge evidence; Agents OFF until G4 PASS. FINAL ref §13, §8 P2. Reviewer FDE-5 (author ≠ sole approver). Gate context: G2. Expected output / completion criteria: Stub rejects superseded/untrusted when hash/status fail; demo recorded | F27: FDE-3 | G27: Critical | H27: Not Started | I27: 46241 | J27: 46241 | L27: D3-T3 | N27: 0 | O27: FDE-5 | P27: G2 | Q27: §13, §8 P2 | R27: Stub rejects superseded/untrusted when hash/status fail; demo recorded
A28: D4 | B28: P2 Domain / G2 | C28: D4-T4 | D28: Independent conflict review (ID/unit/time/authority/lineage) | E28: What to implement: Independent conflict review (ID/unit/time/authority/lineage) Expected functionality: G2 independent review: list open conflicts. Zero “cleaned” values presented as truth. Supports G2 pass criteria. Important considerations: Work only under submission/; preserve immutable challenge evidence; Agents OFF until G4 PASS. FINAL ref §8.2 G2. Reviewer FDE-1 (author ≠ sole approver). Gate context: G2. Expected output / completion criteria: Written list of open conflicts; zero cleaned values presented as truth | F28: FDE-4 | G28: Critical | H28: Not Started | I28: 46241 | J28: 46241 | L28: D4-T2 | N28: 0 | O28: FDE-1 | P28: G2 | Q28: §8.2 G2 | R28: Written list of open conflicts; zero cleaned values presented as truth
A29: D4 | B29: P2 Domain / G2 | C29: D4-T5 | D29: Spot-check sensitive injects INJ-041/059–064 | E29: What to implement: Spot-check sensitive injects INJ-041/059–064 Expected functionality: Deep-read sensitive privacy/access injects. Log findings and purpose/access limits for later privacy artefact and suites. Important considerations: Work only under submission/; preserve immutable challenge evidence; Agents OFF until G4 PASS. FINAL ref §11.1. Reviewer FDE-4 (author ≠ sole approver). Gate context: G2. Expected output / completion criteria: Findings logged; access/purpose limits noted | F29: FDE-5 | G29: Critical | H29: Not Started | I29: 46241 | J29: 46241 | L29: Prior day exit (D3); seat capacity | N29: 0 | O29: FDE-4 | P29: G2 | Q29: §11.1 | R29: Findings logged; access/purpose limits noted
A30: D4 | B30: P2 Domain / G2 | C30: D4-T6 | D30: Business challenge to unjustified KG | E30: What to implement: Business challenge to unjustified KG Expected functionality: Challenge any KG scope that lacks value evidence. Accept/reject with rationale recorded for innovation slot / artefact 08. Important considerations: Work only under submission/; preserve immutable challenge evidence; Agents OFF until G4 PASS. FINAL ref §20, §8.2. Reviewer FDE-2 (author ≠ sole approver). Gate context: G2. Expected output / completion criteria: Review note accept/reject KG scope with rationale | F30: FDE-1 | G30: Critical | H30: Not Started | I30: 46241 | J30: 46241 | L30: Prior day exit (D3); seat capacity | N30: 0 | O30: FDE-2 | P30: G2 | Q30: §20, §8.2 | R30: Review note accept/reject KG scope with rationale
A31: D5 | B31: P3 Architecture / G3 | C31: D5-T1 | D31: Artefacts 10 C4, 11 ADRs (≥10), 12 contracts | E31: What to implement: Artefacts 10 C4, 11 ADRs (≥10), 12 contracts Expected functionality: Produce C4 views, ≥10 ADRs, contract design reconciled to evaluation/contracts schemas. Address brownfield and rollback. Important considerations: Work only under submission/; preserve immutable challenge evidence; Agents OFF until G4 PASS. FINAL ref §8 P3, §12. Reviewer FDE-5 (10–12), FDE-4 (GxP claims) (author ≠ sole approver). Gate context: G3. Expected output / completion criteria: ≥10 ADRs; 12 reconciles with evaluation/contracts/*.schema.json; brownfield/rollback addressed | F31: FDE-3 | G31: Critical | H31: Not Started | I31: 46242 | J31: 46242 | L31: G2 (D4) | N31: 0 | O31: FDE-5 (10–12), FDE-4 (GxP claims) | P31: G3 | Q31: §8 P3, §12 | R31: ≥10 ADRs; 12 reconciles with evaluation/contracts/*.schema.json; brownfield/rollback addressed
A32: D5 | B32: P3 Architecture / G3 | C32: D5-T2 | D32: Shared evidence-resolver (SHA-256 + source_preserved) | E32: What to implement: Shared evidence-resolver (SHA-256 + source_preserved) Expected functionality: Implement shared resolver emitting valid evidence_item fields. Real SHA-256 (64-hex). source_preserved=true. Used by all workflows. Important considerations: Work only under submission/; preserve immutable challenge evidence; Agents OFF until G4 PASS. FINAL ref §11.3, §13. Reviewer FDE-5 (author ≠ sole approver). Gate context: G3. Expected output / completion criteria: Emits valid evidence_item fields; hash is real 64-hex; source_preserved=true | F32: FDE-3 | G32: Critical | H32: Not Started | I32: 46242 | J32: 46242 | L32: D5-T1 | N32: 0 | O32: FDE-5 | P32: G3 | Q32: §11.3, §13 | R32: Emits valid evidence_item fields; hash is real 64-hex; source_preserved=true
A33: D5 | B33: P3 Architecture / G3 | C33: D5-T3 | D33: python -B tools/test_contracts.py green | E33: What to implement: python -B tools/test_contracts.py green Expected functionality: Run contract tester continuously. Must show 3 positive valid and 3 negative invalid samples behaving correctly. Important considerations: Work only under submission/; preserve immutable challenge evidence; Agents OFF until G4 PASS. FINAL ref §4.2, §13. Reviewer FDE-5 (author ≠ sole approver). Gate context: G3. Expected output / completion criteria: 3 positive valid; 3 negative invalid | F33: FDE-3 | G33: Critical | H33: Not Started | I33: 46242 | J33: 46242 | L33: D5-T1; D5-T2 | N33: 0 | O33: FDE-5 | P33: G3 | Q33: §4.2, §13 | R33: 3 positive valid; 3 negative invalid
A34: D5 | B34: P3 Architecture / G3 | C34: D5-T4 | D34: Draft 13–15 GxP/CSA/QRM | E34: What to implement: Draft 13–15 GxP/CSA/QRM Expected functionality: Intended use + GxP boundary. Risk→control→test chains. Address hard-gate RUB-09. Keep AI advisory only. Important considerations: Work only under submission/; preserve immutable challenge evidence; Agents OFF until G4 PASS. FINAL ref §8 P3, §12. Reviewer FDE-5 (author ≠ sole approver). Gate context: G3. Expected output / completion criteria: Intended use + GxP boundary; risks→controls→tests; hard-gate RUB-09 | F34: FDE-4 | G34: Critical | H34: Not Started | I34: 46242 | J34: 46242 | L34: Prior day exit (D4); seat capacity | N34: 0 | O34: FDE-5 | P34: G3 | Q34: §8 P3, §12 | R34: Intended use + GxP boundary; risks→controls→tests; hard-gate RUB-09
A35: D5 | B35: P3 Architecture / G3 | C35: D5-T5 | D35: Threat skeleton; confirm negatives still fail closed | E35: What to implement: Threat skeleton; confirm negatives still fail closed Expected functionality: Skeleton threat model. Confirm disposition/reportability/side-effect samples still rejected by contracts. Important considerations: Work only under submission/; preserve immutable challenge evidence; Agents OFF until G4 PASS. FINAL ref §8 P3. Reviewer FDE-2 (author ≠ sole approver). Gate context: G3. Expected output / completion criteria: Disposition/reportability/side-effect samples still rejected | F35: FDE-5 | G35: Critical | H35: Not Started | I35: 46242 | J35: 46242 | L35: Prior day exit (D4); seat capacity | N35: 0 | O35: FDE-2 | P35: G3 | Q35: §8 P3 | R35: Disposition/reportability/side-effect samples still rejected
A36: D5 | B36: P3 Architecture / G3 | C36: D5-T6 | D36: Domain rules for resolver; contract vs batch/PV facts | E36: What to implement: Domain rules for resolver; contract vs batch/PV facts Expected functionality: Map required schema fields to evidence sources for batch and PV. No silent unit/time conversion. Important considerations: Work only under submission/; preserve immutable challenge evidence; Agents OFF until G4 PASS. FINAL ref §13. Reviewer FDE-3 (author ≠ sole approver). Gate context: G3. Expected output / completion criteria: Written mapping of required schema fields to sources | F36: FDE-2 | G36: Critical | H36: Not Started | I36: 46242 | J36: 46242 | L36: Prior day exit (D4); seat capacity | N36: 0 | O36: FDE-3 | P36: G3 | Q36: §13 | R36: Written mapping of required schema fields to sources
... A39: D5 | B39: P3 Architecture / G3 | C39: D5-T9 | D39: Policies stub: map ten release gates + hard gates | E39: What to implement: Policies stub: map ten release gates + hard gates Expected functionality: Document/code automatic-fail rules for ten release gates and hard gates under evaluation/policies/. Each hard gate named. Important considerations: Work only under submission/; preserve immutable challenge evidence; Agents OFF until G4 PASS. FINAL ref §11.5, §11.8. Reviewer FDE-5 (author ≠ sole approver). Gate context: G3. Expected output / completion criteria: policies/ has ≥1 rule file; each hard gate named | F39: FDE-4 (+FDE-5) | G39: Critical | H39: Not Started | I39: 46242 | J39: 46242 | L39: D5-T8 | N39: 0 | O39: FDE-5 | P39: G3 | Q39: §11.5, §11.8 | R39: policies/ has ≥1 rule file; each hard gate named
A40: D6 | B40: P4 Secure design | C40: D6-T1 | D40: Draft 16 Threat + 17 Privacy | E40: What to implement: Draft 16 Threat + 17 Privacy Expected functionality: Cover injection, poisoning, tool abuse, stale auth, exfil, DoW; purpose limitation. Address hard-gates RUB-10/11. Important considerations: Work only under submission/; preserve immutable challenge evidence; Agents OFF until G4 PASS. FINAL ref §8 P4, §12. Reviewer FDE-4 (author ≠ sole approver). Gate context: day exit / phase checkpoint. Expected output / completion criteria: Covers injection/poisoning/tool abuse/stale auth/exfil/DoW; purpose limitation; hard-gates RUB-10/11 | F40: FDE-5 | G40: High | H40: Not Started | I40: 46243 | J40: 46243 | L40: G3 (D5) | N40: 0 | O40: FDE-4 | Q40: §8 P4, §12 | R40: Covers injection/poisoning/tool abuse/stale auth/exfil/DoW; purpose limitation; hard-gates RUB-10/11
A41: D6 | B41: P4 Secure design | C41: D6-T2 | D41: Write failing prohibited-action + stale-auth tests (INJ-065/066/067) | E41: What to implement: Write failing prohibited-action + stale-auth tests (INJ-065/066/067) Expected functionality: Tests-before-inference: write failing tests for poisoned/unsigned tools and stale auth BEFORE workflow implementation. Fail for the right reason. Important considerations: Work only under submission/; preserve immutable challenge evidence; Agents OFF until G4 PASS. FINAL ref §8 P4, non-negotiable #4. Reviewer FDE-3 (author ≠ sole approver). Gate context: day exit / phase checkpoint. Expected output / completion criteria: Tests exist before WF implementation; fail for correct reason; evidence paths set | F41: FDE-5 | G41: High | H41: Not Started | I41: 46243 | J41: 46243 | L41: D6-T1; D1-T6 | N41: 0 | O41: FDE-3 | Q41: §8 P4, non-negotiable #4 | R41: Tests exist before WF implementation; fail for correct reason; evidence paths set
A42: D6 | B42: P4 Secure design | C42: D6-T3 | D42: Approved vs poisoned tool manifests; signed allowlist; no agent coding | E42: What to implement: Approved vs poisoned tool manifests; signed allowlist; no agent coding Expected functionality: Design signed allowlist and deny path for unsigned/poisoned tools. Confirm agents still OFF (pre-G4). Important considerations: Work only under submission/; preserve immutable challenge evidence; Agents OFF until G4 PASS. FINAL ref §13, agent freeze. Reviewer FDE-5 (author ≠ sole approver). Gate context: day exit / phase checkpoint. Expected output / completion criteria: Design denies unsigned/poisoned tools; confirmation agents still OFF | F42: FDE-3 | G42: High | H42: Not Started | I42: 46243 | J42: 46243 | L42: Prior day exit (D5); seat capacity | N42: 0 | O42: FDE-5 | Q42: §13, agent freeze | R42: Design denies unsigned/poisoned tools; confirmation agents still OFF
A43: D6 | B43: P4 Secure design | C43: D6-T4 | D43: Residual risk register start; GxP impact of controls | E43: What to implement: Residual risk register start; GxP impact of controls Expected functionality: Start residual risk list with owners. No unverified acceptance of residual GxP risk. Important considerations: Work only under submission/; preserve immutable challenge evidence; Agents OFF until G4 PASS. FINAL ref §8 P4. Reviewer FDE-5 (author ≠ sole approver). Gate context: day exit / phase checkpoint. Expected output / completion criteria: Residual risks listed with owners; no unverified acceptance | F43: FDE-4 | G43: High | H43: Not Started | I43: 46243 | J43: 46243 | L43: Prior day exit (D5); seat capacity | N43: 0 | O43: FDE-5 | Q43: §8 P4 | R43: Residual risks listed with owners; no unverified acceptance
A44: D6 | B44: P4 Secure design | C44: D6-T5 | D44: Privacy/purpose data mapping | E44: What to implement: Privacy/purpose data mapping Expected functionality: Map consents, exports, retention conflicts for D09 injects. Support artefact 17 and privacy suite. Important considerations: Work only under submission/; preserve immutable challenge evidence; Agents OFF until G4 PASS. FINAL ref §11.1 D09. Reviewer FDE-5 (author ≠ sole approver). Gate context: day exit / phase checkpoint. Expected output / completion criteria: Mapping cites consents/exports/retention conflicts | F44: FDE-2 | G44: High | H44: Not Started | I44: 46243 | J44: 46243 | L44: Prior day exit (D5); seat capacity | N44: 0 | O44: FDE-5 | Q44: §11.1 D09 | R44: Mapping cites consents/exports/retention conflicts
A45: D6 | B45: P4 Secure design | C45: D6-T6 | D45: HF / automation-bias notes (INJ-071) for artefact 18 | E45: What to implement: HF / automation-bias notes (INJ-071) for artefact 18 Expected functionality: Notes on candidate_outputs and omitted-fact risk for Responsible AI artefact. Cite INJ-071. Important considerations: Work only under submission/; preserve immutable challenge evidence; Agents OFF until G4 PASS. FINAL ref §8 P4. Reviewer FDE-5 (author ≠ sole approver). Gate context: day exit / phase checkpoint. Expected output / completion criteria: Notes cite candidate_outputs / omitted-fact risk | F45: FDE-1 | G45: High | H45: Not Started | I45: 46243 | J45: 46243 | L45: Prior day exit (D5); seat capacity | N45: 0 | O45: FDE-5 | Q45: §8 P4 | R45: Notes cite candidate_outputs / omitted-fact risk
...

Sheet By_Day
A1: Day | B1: Task count | C1: Not Started | D1: In Progress | E1: Blocked | F1: Completed | G1: On Hold | H1: Avg completion
A2: D1 | B2: 9 | C2: =COUNTIFS(Task_Tracker!A:A,A2,Task_Tracker!H:H,"Not Started") | D2: =COUNTIFS(Task_Tracker!A:A,A2,Task_Tracker!H:H,"In Progress") | E2: =COUNTIFS(Task_Tracker!A:A,A2,Task_Tracker!H:H,"Blocked") | F2: =COUNTIFS(Task_Tracker!A:A,A2,Task_Tracker!H:H,"Completed") | G2: =COUNTIFS(Task_Tracker!A:A,A2,Task_Tracker!H:H,"On Hold") | H2: =IFERROR(AVERAGEIF(Task_Tracker!A:A,A2,Task_Tracker!N:N),0)
A3: D2 | B3: 7 | C3: =COUNTIFS(Task_Tracker!A:A,A3,Task_Tracker!H:H,"Not Started") | D3: =COUNTIFS(Task_Tracker!A:A,A3,Task_Tracker!H:H,"In Progress") | E3: =COUNTIFS(Task_Tracker!A:A,A3,Task_Tracker!H:H,"Blocked") | F3: =COUNTIFS(Task_Tracker!A:A,A3,Task_Tracker!H:H,"Completed") | G3: =COUNTIFS(Task_Tracker!A:A,A3,Task_Tracker!H:H,"On Hold") | H3: =IFERROR(AVERAGEIF(Task_Tracker!A:A,A3,Task_Tracker!N:N),0)
A4: D3 | B4: 7 | C4: =COUNTIFS(Task_Tracker!A:A,A4,Task_Tracker!H:H,"Not Started") | D4: =COUNTIFS(Task_Tracker!A:A,A4,Task_Tracker!H:H,"In Progress") | E4: =COUNTIFS(Task_Tracker!A:A,A4,Task_Tracker!H:H,"Blocked") | F4: =COUNTIFS(Task_Tracker!A:A,A4,Task_Tracker!H:H,"Completed") | G4: =COUNTIFS(Task_Tracker!A:A,A4,Task_Tracker!H:H,"On Hold") | H4: =IFERROR(AVERAGEIF(Task_Tracker!A:A,A4,Task_Tracker!N:N),0)
A5: D4 | B5: 6 | C5: =COUNTIFS(Task_Tracker!A:A,A5,Task_Tracker!H:H,"Not Started") | D5: =COUNTIFS(Task_Tracker!A:A,A5,Task_Tracker!H:H,"In Progress") | E5: =COUNTIFS(Task_Tracker!A:A,A5,Task_Tracker!H:H,"Blocked") | F5: =COUNTIFS(Task_Tracker!A:A,A5,Task_Tracker!H:H,"Completed") | G5: =COUNTIFS(Task_Tracker!A:A,A5,Task_Tracker!H:H,"On Hold") | H5: =IFERROR(AVERAGEIF(Task_Tracker!A:A,A5,Task_Tracker!N:N),0)
A6: D5 | B6: 9 | C6: =COUNTIFS(Task_Tracker!A:A,A6,Task_Tracker!H:H,"Not Started") | D6: =COUNTIFS(Task_Tracker!A:A,A6,Task_Tracker!H:H,"In Progress") | E6: =COUNTIFS(Task_Tracker!A:A,A6,Task_Tracker!H:H,"Blocked") | F6: =COUNTIFS(Task_Tracker!A:A,A6,Task_Tracker!H:H,"Completed") | G6: =COUNTIFS(Task_Tracker!A:A,A6,Task_Tracker!H:H,"On Hold") | H6: =IFERROR(AVERAGEIF(Task_Tracker!A:A,A6,Task_Tracker!N:N),0)
A7: D6 | B7: 7 | C7: =COUNTIFS(Task_Tracker!A:A,A7,Task_Tracker!H:H,"Not Started") | D7: =COUNTIFS(Task_Tracker!A:A,A7,Task_Tracker!H:H,"In Progress") | E7: =COUNTIFS(Task_Tracker!A:A,A7,Task_Tracker!H:H,"Blocked") | F7: =COUNTIFS(Task_Tracker!A:A,A7,Task_Tracker!H:H,"Completed") | G7: =COUNTIFS(Task_Tracker!A:A,A7,Task_Tracker!H:H,"On Hold") | H7: =IFERROR(AVERAGEIF(Task_Tracker!A:A,A7,Task_Tracker!N:N),0)
A8: D7 | B8: 6 | C8: =COUNTIFS(Task_Tracker!A:A,A8,Task_Tracker!H:H,"Not Started") | D8: =COUNTIFS(Task_Tracker!A:A,A8,Task_Tracker!H:H,"In Progress") | E8: =COUNTIFS(Task_Tracker!A:A,A8,Task_Tracker!H:H,"Blocked") | F8: =COUNTIFS(Task_Tracker!A:A,A8,Task_Tracker!H:H,"Completed") | G8: =COUNTIFS(Task_Tracker!A:A,A8,Task_Tracker!H:H,"On Hold") | H8: =IFERROR(AVERAGEIF(Task_Tracker!A:A,A8,Task_Tracker!N:N),0)
A9: D8 | B9: 8 | C9: =COUNTIFS(Task_Tracker!A:A,A9,Task_Tracker!H:H,"Not Started") | D9: =COUNTIFS(Task_Tracker!A:A,A9,Task_Tracker!H:H,"In Progress") | E9: =COUNTIFS(Task_Tracker!A:A,A9,Task_Tracker!H:H,"Blocked") | F9: =COUNTIFS(Task_Tracker!A:A,A9,Task_Tracker!H:H,"Completed") | G9: =COUNTIFS(Task_Tracker!A:A,A9,Task_Tracker!H:H,"On Hold") | H9: =IFERROR(AVERAGEIF(Task_Tracker!A:A,A9,Task_Tracker!N:N),0)
A10: D9 | B10: 6 | C10: =COUNTIFS(Task_Tracker!A:A,A10,Task_Tracker!H:H,"Not Started") | D10: =COUNTIFS(Task_Tracker!A:A,A10,Task_Tracker!H:H,"In Progress") | E10: =COUNTIFS(Task_Tracker!A:A,A10,Task_Tracker!H:H,"Blocked") | F10: =COUNTIFS(Task_Tracker!A:A,A10,Task_Tracker!H:H,"Completed") | G10: =COUNTIFS(Task_Tracker!A:A,A10,Task_Tracker!H:H,"On Hold") | H10: =IFERROR(AVERAGEIF(Task_Tracker!A:A,A10,Task_Tracker!N:N),0)
A11: D10 | B11: 9 | C11: =COUNTIFS(Task_Tracker!A:A,A11,Task_Tracker!H:H,"Not Started") | D11: =COUNTIFS(Task_Tracker!A:A,A11,Task_Tracker!H:H,"In Progress") | E11: =COUNTIFS(Task_Tracker!A:A,A11,Task_Tracker!H:H,"Blocked") | F11: =COUNTIFS(Task_Tracker!A:A,A11,Task_Tracker!H:H,"Completed") | G11: =COUNTIFS(Task_Tracker!A:A,A11,Task_Tracker!H:H,"On Hold") | H11: =IFERROR(AVERAGEIF(Task_Tracker!A:A,A11,Task_Tracker!N:N),0)
A12: D11 | B12: 5 | C12: =COUNTIFS(Task_Tracker!A:A,A12,Task_Tracker!H:H,"Not Started") | D12: =COUNTIFS(Task_Tracker!A:A,A12,Task_Tracker!H:H,"In Progress") | E12: =COUNTIFS(Task_Tracker!A:A,A12,Task_Tracker!H:H,"Blocked") | F12: =COUNTIFS(Task_Tracker!A:A,A12,Task_Tracker!H:H,"Completed") | G12: =COUNTIFS(Task_Tracker!A:A,A12,Task_Tracker!H:H,"On Hold") | H12: =IFERROR(AVERAGEIF(Task_Tracker!A:A,A12,Task_Tracker!N:N),0)
A13: D12 | B13: 6 | C13: =COUNTIFS(Task_Tracker!A:A,A13,Task_Tracker!H:H,"Not Started") | D13: =COUNTIFS(Task_Tracker!A:A,A13,Task_Tracker!H:H,"In Progress") | E13: =COUNTIFS(Task_Tracker!A:A,A13,Task_Tracker!H:H,"Blocked") | F13: =COUNTIFS(Task_Tracker!A:A,A13,Task_Tracker!H:H,"Completed") | G13: =COUNTIFS(Task_Tracker!A:A,A13,Task_Tracker!H:H,"On Hold") | H13: =IFERROR(AVERAGEIF(Task_Tracker!A:A,A13,Task_Tracker!N:N),0)
... A15: D14 | B15: 1 | C15: =COUNTIFS(Task_Tracker!A:A,A15,Task_Tracker!H:H,"Not Started") | D15: =COUNTIFS(Task_Tracker!A:A,A15,Task_Tracker!H:H,"In Progress") | E15: =COUNTIFS(Task_Tracker!A:A,A15,Task_Tracker!H:H,"Blocked") | F15: =COUNTIFS(Task_Tracker!A:A,A15,Task_Tracker!H:H,"Completed") | G15: =COUNTIFS(Task_Tracker!A:A,A15,Task_Tracker!H:H,"On Hold") | H15: =IFERROR(AVERAGEIF(Task_Tracker!A:A,A15,Task_Tracker!N:N),0)

Sheet Gate_Board
A1: Gate | B1: Day | C1: Evaluation question | D1: Reviewers | E1: Pass criteria | F1: Gate result | G1: Notes
A2: Preflight | B2: D1 | C2: Package integrity baseline + team ready? | D2: Full team | E2: Hour-0 PASS archived; seats named; FINAL ratified; --scaffold PASS
A3: G1 | B3: D2 | C3: Problem measurable; no-AI honest; NFRs locked? | D3: FDE-4 + FDE-5 | E3: 01–04 drafted with citations; no-AI table present; NFR table locked; stop/pivot stated
A4: G2 | B4: D4 | C4: Conflicts tracked not silently resolved; inject register real? | D4: FDE-1 + FDE-4 | E4: Conflict list exists; register 84 rows ≠ silent delete; no cleaned units/IDs
A5: G3 | B5: D5 | C5: Prohibited actions outside executable boundary? | D5: FDE-2 + FDE-5 | E5: test_contracts 3+/3−; design forbids disposition/reportability/side effects
A6: G4 | B6: D7 | C6: Threat/privacy/ISO controls + failing prohibited tests exist? | D6: FDE-1 + FDE-3 | E6: 16–21 drafted; prohibited/stale-auth tests fail for right reason before WF code
A7: G5 | B7: D9 | C7: Three workflows run offline against fixtures? | D7: FDE-1 + FDE-4 | E7: A/B/C offline; schema-valid; demo happy + abstain; AI-disabled path shown
A8: G6 | B8: D10 | C8: Red-team / outage / cost gates fail closed as designed? | D8: FDE-2 + FDE-3 | E8: Suites evidence; failed-gate demo; thresholds pre-committed
A9: G7 | B9: D10 | C9: Clean-room + --final + hash --check? | D9: Full team + outsider | E9: Clean extract succeeds; hashes match; --final PASS
A10: G8 | B10: D10 | C10: 13 defence elements rehearsed; recommendation clear? | D10: Full team | E10: Presenters named; go/conditional/pivot/pause/stop recorded
A11: G9 | B11: D13 | C11: Readiness Board; Blockers=0; RC clean-room? | D11: FDE-4 chairs | E11: 28 complete; hard gates on RC; RC clean-room; P1/P4/P5 signs
